<?xml version="1.0"?>
<sdf version="1.11" xmlns:xacro="http://www.ros.org/wiki/xacro">
  <xacro:macro name="create_thruster" params="name pose">
    <model name="${name}">
      <pose relative_to="__model__" degrees="true">${pose}</pose>
      <link name="${name}/base_link">
        <inertial>
          <mass>0.5</mass>
        </inertial>
        <collision name="${name}/shroud_collision">
          <pose relative_to="__model__" degrees="true">-0.025 0 0 0 0 -90</pose>
          <geometry>
            <box>
              <size>0.1 0.05 0.1</size>
            </box>
          </geometry>
        </collision>
        <visual name="${name}/shroud_visual">
          <pose relative_to="__model__" degrees="true">0 0 0 0 0 -90</pose>
          <geometry>
            <mesh>
              <scale>0.01 0.01 0.01</scale>
              <uri>meshes/shroud_1/body1_visual.obj</uri>
            </mesh>
          </geometry>
        </visual>
        <visual name="${name}/motor_visual">
          <pose relative_to="__model__" degrees="true">0 0 0 0 0 -90</pose>
          <geometry>
            <mesh>
              <scale>0.01 0.01 0.01</scale>
              <uri>meshes/motor_1/body2_visual.obj</uri>
            </mesh>
          </geometry>
        </visual>
      </link>
      <link name="${name}/propeller">
        <inertial>
          <mass>0.0001</mass>
        </inertial>
        <collision name="${name}/propeller_collision">
          <pose relative_to="__model__" degrees="true">-0.007 0 0 0 0 -90</pose>
          <geometry>
            <box>
              <size>0.05 0.007 0.05</size>
            </box>
          </geometry>
        </collision>
        <visual name="${name}/propeller_visual">
          <pose relative_to="__model__" degrees="true">0 0 0 0 0 -90</pose>
          <geometry>
            <mesh>
              <scale>0.01 0.01 0.01</scale>
              <uri>meshes/propeller_1/body1_visual.obj</uri>
            </mesh>
          </geometry>
        </visual>
      </link>
      <joint name="${name}/prop_joint" type="revolute">
        <pose relative_to="__model__">-0.0125 0 0 0 0 0</pose>
        <parent>${name}/base_link</parent>
        <child>${name}/propeller</child>
        <axis>
          <xyz expressed_in="__model__">1 0 0</xyz>
        </axis>
      </joint>
      <plugin
        filename="gz-sim-thruster-system"
        name="gz::sim::systems::Thruster">
        <namespace>blobfish/thruster</namespace>
        <topic>${name}</topic>
        <joint_name>${name}/prop_joint</joint_name>
        <thrust_coefficient>0.05</thrust_coefficient>
        <fluid_density>1000</fluid_density>
        <propeller_diameter>0.076</propeller_diameter>
      </plugin>
    </model>
  </xacro:macro>
</sdf>
