<?xml version="1.0"?>
<sdf version="1.11">
  <model name="thruster_v5">
    <link name="base_link">
      <pose relative_to="__model__">0 -0.002 0 0 0 0</pose>
      <inertial>
        <mass>0.5</mass>
      </inertial>
      <collision
        name="shroud_1__body1_collision">
        <pose relative_to="__model__">0.0 -0.025 0.0 -0.0 -1.5707963267948966 0</pose>
        <geometry>
          <box>
            <size>0.1 0.05 0.1</size>
          </box>
        </geometry>
      </collision>
      <visual name="motor_1__body2_visual">
        <geometry>
          <mesh>
            <scale>0.01 0.01 0.01</scale>
            <uri>meshes/motor_1/body2_visual.obj</uri>
          </mesh>
        </geometry>
      </visual>
      <visual name="shroud_1__body1_visual">
        <geometry>
          <mesh>
            <scale>0.01 0.01 0.01</scale>
            <uri>meshes/shroud_1/body1_visual.obj</uri>
          </mesh>
        </geometry>
      </visual>
    </link>
    <link name="propeller_1">
      <pose>0 0.002 0 0 0 0</pose>
      <inertial>
        <mass>0.0001</mass>
      </inertial>
      <visual name="propeller_1__body1_visual">
        <geometry>
          <mesh>
            <scale>0.01 0.01 0.01</scale>
            <uri>meshes/propeller_1/body1_visual.obj</uri>
          </mesh>
        </geometry>
      </visual>
      <collision name="propeller_1__body1_collision">
        <pose relative_to="__model__">0 -0.007 0 0 0 0</pose>
        <geometry>
          <box>
            <size>0.05 0.007 0.05</size>
          </box>
        </geometry>
      </collision>
    </link>
    <joint name="prop_joint" type="revolute">
      <pose relative_to="__model__">0 -0.015 0 0 0 0</pose>
      <parent>base_link</parent>
      <child>propeller_1</child>
      <axis>
        <xyz expressed_in="__model__">0 1 0</xyz>
        <limit>
          <lower>-1e+12</lower>
          <upper>1e+12</upper>
          <effort>-1</effort>
          <velocity>-1</velocity>
        </limit>
      </axis>
    </joint>
  </model>
</sdf>
